2025-02-28 18:07:32,715:ERROR:Error processing product: Invalid control character at: line 8 column 44 (char 202)
Traceback (most recent call last):
  File "C:\Users\user_\Downloads\Data&Data\Data&Data - PriceAnalysis Challenge\Data-Data-Challenge\src\scraper\utils.py", line 51, in extract_product_info
    data_tracking = json.loads(data_tracking.replace("&quot;", '"'))
  File "C:\Users\user_\AppData\Local\Programs\Python\Python38\lib\json\__init__.py", line 357, in loads
    return _default_decoder.decode(s)
  File "C:\Users\user_\AppData\Local\Programs\Python\Python38\lib\json\decoder.py", line 337, in decode
    obj, end = self.raw_decode(s, idx=_w(s, 0).end())
  File "C:\Users\user_\AppData\Local\Programs\Python\Python38\lib\json\decoder.py", line 353, in raw_decode
    obj, end = self.scan_once(s, idx)
json.decoder.JSONDecodeError: Invalid control character at: line 8 column 44 (char 202)
2025-02-28 18:07:32,749:ERROR:Error in data_extraction for Japan: 'NoneType' object does not support item assignment
Traceback (most recent call last):
  File "C:\Users\user_\Downloads\Data&Data\Data&Data - PriceAnalysis Challenge\Data-Data-Challenge\src\scraper\utils.py", line 131, in extract
    product_info["country"] = country
TypeError: 'NoneType' object does not support item assignment
2025-02-28 18:07:48,700:ERROR:clean_data: Removed 4 rows with missing values
NoneType: None
2025-02-28 18:07:48,713:ERROR:transform_data: 147 missing currency mappings
NoneType: None
2025-02-28 18:07:48,813:ERROR:Network error: 429 Client Error: Too Many Requests for url: https://v6.exchangerate-api.com/v6/83d54a3093c0bb5485892f13/latest/EUR
Traceback (most recent call last):
  File "C:\Users\user_\Downloads\Data&Data\Data&Data - PriceAnalysis Challenge\Data-Data-Challenge\src\scraper\utils.py", line 163, in get_exchange_rate
    response.raise_for_status()
  File "C:\Users\user_\Downloads\Data&Data\Data&Data - PriceAnalysis Challenge\Data-Data-Challenge\virtualenv\lib\site-packages\requests\models.py", line 1024, in raise_for_status
    raise HTTPError(http_error_msg, response=self)
requests.exceptions.HTTPError: 429 Client Error: Too Many Requests for url: https://v6.exchangerate-api.com/v6/83d54a3093c0bb5485892f13/latest/EUR
2025-02-28 18:07:48,816:ERROR:transform_data: Currency conversion failed - unsupported operand type(s) for *: 'float' and 'NoneType'
Traceback (most recent call last):
  File "C:\Users\user_\Downloads\Data&Data\Data&Data - PriceAnalysis Challenge\Data-Data-Challenge\src\scraper\utils.py", line 309, in transform_data
    df[f"price_{target_currency}"] = df.apply(
  File "C:\Users\user_\Downloads\Data&Data\Data&Data - PriceAnalysis Challenge\Data-Data-Challenge\virtualenv\lib\site-packages\pandas\core\frame.py", line 9423, in apply
    return op.apply().__finalize__(self, method="apply")
  File "C:\Users\user_\Downloads\Data&Data\Data&Data - PriceAnalysis Challenge\Data-Data-Challenge\virtualenv\lib\site-packages\pandas\core\apply.py", line 678, in apply
    return self.apply_standard()
  File "C:\Users\user_\Downloads\Data&Data\Data&Data - PriceAnalysis Challenge\Data-Data-Challenge\virtualenv\lib\site-packages\pandas\core\apply.py", line 798, in apply_standard
    results, res_index = self.apply_series_generator()
  File "C:\Users\user_\Downloads\Data&Data\Data&Data - PriceAnalysis Challenge\Data-Data-Challenge\virtualenv\lib\site-packages\pandas\core\apply.py", line 814, in apply_series_generator
    results[i] = self.f(v)
  File "C:\Users\user_\Downloads\Data&Data\Data&Data - PriceAnalysis Challenge\Data-Data-Challenge\src\scraper\utils.py", line 310, in <lambda>
    lambda row: row["price"] * get_exchange_rate(row["currency_code"], target_currency) if row["currency_code"] in CURRENCIES_CODE.values() else None,
TypeError: unsupported operand type(s) for *: 'float' and 'NoneType'
